[2024-12-23 10:34:14,260] {taskinstance.py:896} INFO - Dependencies all met for <TaskInstance: warsaw_data_update_dag.warsaw_data_update_dag_script 2024-12-23T10:20:00+00:00 [queued]>
[2024-12-23 10:34:14,282] {taskinstance.py:896} INFO - Dependencies all met for <TaskInstance: warsaw_data_update_dag.warsaw_data_update_dag_script 2024-12-23T10:20:00+00:00 [queued]>
[2024-12-23 10:34:14,282] {taskinstance.py:1087} INFO - 
--------------------------------------------------------------------------------
[2024-12-23 10:34:14,282] {taskinstance.py:1088} INFO - Starting attempt 1 of 1
[2024-12-23 10:34:14,282] {taskinstance.py:1089} INFO - 
--------------------------------------------------------------------------------
[2024-12-23 10:34:14,299] {taskinstance.py:1107} INFO - Executing <Task(BashOperator): warsaw_data_update_dag_script> on 2024-12-23T10:20:00+00:00
[2024-12-23 10:34:14,304] {standard_task_runner.py:52} INFO - Started process 1513 to run task
[2024-12-23 10:34:14,308] {standard_task_runner.py:76} INFO - Running: ['***', 'tasks', 'run', 'warsaw_data_update_dag', 'warsaw_data_update_dag_script', '2024-12-23T10:20:00+00:00', '--job-id', '7', '--pool', 'default_pool', '--raw', '--subdir', 'DAGS_FOLDER/warsaw.py', '--cfg-path', '/tmp/tmp20frlzbm', '--error-file', '/tmp/tmp2f_8nh93']
[2024-12-23 10:34:14,309] {standard_task_runner.py:77} INFO - Job 7: Subtask warsaw_data_update_dag_script
[2024-12-23 10:34:14,371] {logging_mixin.py:104} INFO - Running <TaskInstance: warsaw_data_update_dag.warsaw_data_update_dag_script 2024-12-23T10:20:00+00:00 [running]> on host 21ac49de6db4
[2024-12-23 10:34:14,446] {taskinstance.py:1302} INFO - Exporting the following env vars:
AIRFLOW_CTX_DAG_OWNER=***
AIRFLOW_CTX_DAG_ID=warsaw_data_update_dag
AIRFLOW_CTX_TASK_ID=warsaw_data_update_dag_script
AIRFLOW_CTX_EXECUTION_DATE=2024-12-23T10:20:00+00:00
AIRFLOW_CTX_DAG_RUN_ID=scheduled__2024-12-23T10:20:00+00:00
[2024-12-23 10:34:14,447] {subprocess.py:52} INFO - Tmp dir root location: 
 /tmp
[2024-12-23 10:34:14,447] {subprocess.py:63} INFO - Running command: ['bash', '-c', 'cd /opt/***/scripts/ && python warsawUpdate.py']
[2024-12-23 10:34:14,459] {subprocess.py:75} INFO - Output:
[2024-12-23 10:34:15,371] {subprocess.py:79} INFO - /home/***/.local/lib/python3.6/site-packages/urllib3/connectionpool.py:988: InsecureRequestWarning: Unverified HTTPS request is being made to host 'api.openweathermap.org'. Adding certificate verification is strongly advised. See: https://urllib3.readthedocs.io/en/latest/advanced-usage.html#ssl-warnings
[2024-12-23 10:34:15,371] {subprocess.py:79} INFO -   InsecureRequestWarning,
[2024-12-23 10:34:15,371] {subprocess.py:79} INFO - /home/***/.local/lib/python3.6/site-packages/urllib3/connectionpool.py:988: InsecureRequestWarning: Unverified HTTPS request is being made to host 'api.openweathermap.org'. Adding certificate verification is strongly advised. See: https://urllib3.readthedocs.io/en/latest/advanced-usage.html#ssl-warnings
[2024-12-23 10:34:15,371] {subprocess.py:79} INFO -   InsecureRequestWarning,
[2024-12-23 10:34:15,371] {subprocess.py:79} INFO - /home/***/.local/lib/python3.6/site-packages/urllib3/connectionpool.py:988: InsecureRequestWarning: Unverified HTTPS request is being made to host 'api.openweathermap.org'. Adding certificate verification is strongly advised. See: https://urllib3.readthedocs.io/en/latest/advanced-usage.html#ssl-warnings
[2024-12-23 10:34:15,371] {subprocess.py:79} INFO -   InsecureRequestWarning,
[2024-12-23 10:34:15,371] {subprocess.py:79} INFO - /home/***/.local/lib/python3.6/site-packages/urllib3/connectionpool.py:988: InsecureRequestWarning: Unverified HTTPS request is being made to host 'api.openweathermap.org'. Adding certificate verification is strongly advised. See: https://urllib3.readthedocs.io/en/latest/advanced-usage.html#ssl-warnings
[2024-12-23 10:34:15,371] {subprocess.py:79} INFO -   InsecureRequestWarning,
[2024-12-23 10:34:15,377] {subprocess.py:79} INFO - Error: 401 Client Error: Unauthorized for url: https://api.openweathermap.org/data/2.5/weather?q=Warsaw&appid=apikey&units=metric
[2024-12-23 10:34:15,377] {subprocess.py:79} INFO - Error: 401 Client Error: Unauthorized for url: https://api.openweathermap.org/data/2.5/weather?q=Barcelona&appid=apikey&units=metric
[2024-12-23 10:34:15,377] {subprocess.py:79} INFO - Error: 401 Client Error: Unauthorized for url: https://api.openweathermap.org/data/2.5/weather?q=Paris&appid=apikey&units=metric
[2024-12-23 10:34:15,377] {subprocess.py:79} INFO - Error: 401 Client Error: Unauthorized for url: https://api.openweathermap.org/data/2.5/weather?q=Berlin&appid=apikey&units=metric
[2024-12-23 10:34:15,402] {subprocess.py:83} INFO - Command exited with return code 0
[2024-12-23 10:34:15,443] {taskinstance.py:1211} INFO - Marking task as SUCCESS. dag_id=warsaw_data_update_dag, task_id=warsaw_data_update_dag_script, execution_date=20241223T102000, start_date=20241223T103414, end_date=20241223T103415
[2024-12-23 10:34:15,478] {taskinstance.py:1265} INFO - 0 downstream tasks scheduled from follow-on schedule check
[2024-12-23 10:34:15,543] {local_task_job.py:151} INFO - Task exited with return code 0
